Workbook

Sheet Executive_Summary
A1: NimbusDesk FY26 Annual Operating Plan Executive Summary
A4: Executive Summary
A5: NimbusDesk's FY26 Annual Operating Plan targets FY26 Revenue of $27.2M while achieving operating cash flow breakeven in October FY26 and ending the year with approximately $26.7M in cash. The business continues to demonstrate strong SaaS fundamentals, including 109% Net Revenue Retention, 83% Gross Margin, and an LTV:CAC ratio of 4.8x. Although the company remains loss-making during FY26, operating cash burn reduces steadily throughout the year, supporting a sustainable path toward profitability. STEP 4 – FY26 Operating Plan Step 4.1 Merge A11:L11 Type: FY26 Operating Plan Format: Font Size: 14 Bold Dark Blue Fill White Font Step 4.2 Merge A12:L16 Turn Wrap Text ON. Paste: • FY26 Revenue planned at $27.2M, supported by recurring subscription revenue growth. • Operating cash flow expected to reach breakeven in October FY26. • Maintain strong SaaS unit economics with 109% NRR, 83% Gross Margin, 4.8x LTV:CAC, and 19-month CAC Payback. • Planned headcount growth from 139 to 151 employees, aligned with business growth. STEP 5 – Key Risks Step 5.1 Merge A18:L18 Type: Key Risks Format like the previous headings. Step 5.2 Merge A19:L25 Turn Wrap Text ON. Paste: • Gross Revenue Retention remains at 81%, indicating continued customer churn risk. • Sales capacity currently exceeds New ARR generation, reducing commercial efficiency. • Revenue growth assumptions rely on continued customer expansion and retention improvements. • Q1 variance analysis identified higher operating expenses together with weaker New ARR, increasing pressure on the planned cash breakeven timeline. Stop here. Don't build the rest yet. Your sheet should now have: ✅ Title ✅ Executive Summary ✅ FY26 Operating Plan ✅ Key Risks Send me a screenshot after you've completed these sections. Then we'll build: Scenario Assessment Management Recommendations Conclusion These are the final three sections of your FP&A project.
A11: FY26 Operating Plan
A12: • FY26 Revenue planned at $27.2M, supported by recurring subscription revenue growth. • Operating cash flow expected to reach breakeven in October FY26. • Maintain strong SaaS unit economics with 109% NRR, 83% Gross Margin, 4.8x LTV:CAC, and 19-month CAC Payback. • Planned headcount growth from 139 to 151 employees, aligned with business growth.
A18: Key Risks
A19: Gross Revenue Retention remains at 81%, indicating continued customer churn risk. • Sales capacity currently exceeds New ARR generation, reducing commercial efficiency. • Revenue growth assumptions rely on continued customer expansion and retention improvements. • Q1 variance analysis identified higher operating expenses together with weaker New ARR, increasing pressure on the planned cash breakeven timeline.
A29: Scenario Assessment
A30: Scenario analysis confirms that NimbusDesk remains financially resilient across multiple operating environments. Under the Base Case, the company achieves operating cash flow breakeven in October FY26 while maintaining approximately $26.7M in year-end cash. The Upside Case accelerates profitability through stronger customer acquisition and expansion revenue, while the Downside Case delays breakeven but still maintains sufficient liquidity to support operations. The scenario framework provides management with flexibility to adjust hiring and operating expenses based on business performance.
A37: Management Recommendations
A38: • Prioritize customer retention initiatives to improve Gross Revenue Retention and reduce customer churn. • Improve sales productivity before increasing Sales & Marketing investment, ensuring existing sales capacity delivers stronger customer acquisition. • Continue monthly Budget vs Actual reviews and rolling forecasts to identify risks early and adjust operating plans proactively. • Maintain disciplined hiring using the scenario planning framework, allowing operating expenses to scale in line with revenue performance.
A50: Conclusion
A51: NimbusDesk enters FY26 with a financially disciplined operating plan supported by strong recurring revenue economics, integrated financial planning, and a robust scenario framework. While customer retention, commercial efficiency, and operating cost control remain key execution priorities, the company maintains sufficient financial flexibility to achieve its long-term growth objectives. Continued monitoring through variance analysis and rolling forecasts will enable management to respond proactively to changing business conditions and support sustainable value creation.

Sheet Dashboard
A1: NimbusDesk FY26 Annual Operating Plan
A4: Current Scenario | B4: =CHOOSE(Scenarios!F2,"Base","Upside","Downside") -> Base
A6: FY26 Revenue | C6: Ending ARR | E6: NRR | G6: GRR | I6: Gross Margin | K6: EBITDA
A7: =Rev_Build!N18 -> 27204155 | C7: =Rev_Build!M15 -> 30322700 | E7: =Customer_Metrics!B16 -> 1.0873107 | G7: =Customer_Metrics!B15 -> 0.81403338 | I7: =Three_Statement!N5 -> 0.83996384 | K7: =Three_Statement!O7 -> -2486073.6
A10: LTV:CAC | C10: CAC Payback | E10: December Cash | G10: Headcount | I10: Revenue / Employee | K10: Cash Breakeven
A11: =Customer_Metrics!B22 -> 4.8447205 | C11: =Customer_Metrics!B19 -> 19.071479 | E11: =Three_Statement!N59 -> 26652360 | G11: =Headcount_Plan!B48 -> 138.6 | I11: =Rev_Build!N18/Headcount_Plan!B48 -> 196278.17 | K11: =Cash_Flow!B17 -> October FY26

Sheet Assumptions_Log
A1: Assumptions_Log
A2: Category | B2: Observation | C2: Status
A3: Customer Retention | B3: GRR of 81% indicates customer retention weakness; expansion revenue currently masks underlying churn. | C3: Risk
A4: Revenue Assumption | B4: Expansion rate increased to 2.4% to achieve 109% NRR; operational execution must support this assumption. | C4: Monitor
A5: People Cost | B5: People cost equals 74.6% of revenue, creating pressure on operating leverage and burn reduction. | C5: Monitor
A6: Sales Capacity | B6: Sales capacity exceeds New ARR target by approximately 3x, suggesting either an understated revenue plan or excess sales capacity. | C6: Risk
A7: Budget Allocation | B7: Sales & Marketing represents 36% of OpEx while Customer Success receives only 10%, despite customer retention being the primary operational challenge. | C7: Recommendation
A8: Cash Flow | B8: Operating cash flow reaches breakeven in October FY26. Timing remains conservative because deferred revenue has not yet been modeled. | C8: Key Finding
A9: Reporting Currency | B9: The model reports in USD. Salary costs are modeled in AED and converted to USD once at the Headcount_Plan boundary using an exchange rate of 3.67 AED/USD. | C9: Model Convention
A10: Gross Margin | B10: Bottom-up cost build produces an 83% gross margin compared with the initial planning assumption of 78%; the model carries forward the bottom-up result. | C10: Model Convention

Sheet Rev_Build
A1: Beginning ARR (Jan) | B1: 24000000
A2: New ARR - Q1 monthly | B2: =CHOOSE(Scenarios!$F$2,Scenarios!$B$2,Scenarios!$C$2,Scenarios!$D$2) -> 280000
A3: New ARR MoM growth (post-Q1) | B3: =CHOOSE(Scenarios!$F$2,Scenarios!$B$3,Scenarios!$C$3,Scenarios!$D$3) -> 0.05
A4: Monthly churn % | B4: =CHOOSE(Scenarios!$F$2,Scenarios!$B$5,Scenarios!$C$5,Scenarios!$D$5) -> 0.013
A5: Monthly expansion % | B5: =CHOOSE(Scenarios!$F$2,Scenarios!$B$4,Scenarios!$C$4,Scenarios!$D$4) -> 0.024
A6: Monthly contraction % | B6: =CHOOSE(Scenarios!$F$2,Scenarios!$B$6,Scenarios!$C$6,Scenarios!$D$6) -> 0.004
B9: Jan | C9: Feb | D9: Mar | E9: Apr | F9: May | G9: Jun | H9: Jul | I9: Aug | J9: Sep | K9: Oct | L9: Nov | M9: Dec | N9: Total
A10: Beginning ARR | B10: =B1 -> 24000000 | C10: =B15 -> 24448000 | D10: =C15 -> 24899136 | E10: =D15 -> 25353430 | F10: =E15 -> 25824904 | G10: =F15 -> 26314378 | H10: =G15 -> 26822714 | I10: =H15 -> 27350815 | J10: =I15 -> 27899629 | ... M10: =L15 -> 29680564 | N10: =SUM(B10:M10) -> 3.2012716e+08
A11: New ARR | B11: =B2 -> 280000 | C11: =$B$2 -> 280000 | D11: =$B$2 -> 280000 | E11: =D11*(1+$B$3) -> 294000 | F11: =E11*(1+$B$3) -> 308700 | G11: =F11*(1+$B$3) -> 324135 | H11: =G11*(1+$B$3) -> 340341.75 | I11: =H11*(1+$B$3) -> 357358.84 | J11: =I11*(1+$B$3) -> 375226.78 | K11: =J11*(1+$B$3) -> 393988.12 | L11: =K11*(1+$B$3) -> 413687.52 | M11: =L11*(1+$B$3) -> 434371.9 | N11: =SUM(B11:M11) -> 4081809.9
A12: Expansion | B12: =B10*$B$5 -> 576000 | C12: =C10*$B$5 -> 586752 | D12: =D10*$B$5 -> 597579.26 | E12: =E10*$B$5 -> 608482.32 | F12: =F10*$B$5 -> 619797.7 | G12: =G10*$B$5 -> 631545.08 | H12: =H10*$B$5 -> 643745.13 | I12: =I10*$B$5 -> 656419.55 | ... M12: =M10*$B$5 -> 712333.54 | N12: =SUM(B12:M12) -> 7683051.7
A13: Churn | B13: =-B10*$B$4 -> -312000 | C13: =-C10*$B$4 -> -317824 | D13: =-D10*$B$4 -> -323688.77 | E13: =-E10*$B$4 -> -329594.59 | F13: =-F10*$B$4 -> -335723.75 | G13: =-G10*$B$4 -> -342086.92 | H13: =-H10*$B$4 -> -348695.28 | I13: =-I10*$B$4 -> -355560.59 | ... M13: =-M10*$B$4 -> -385847.33 | N13: =SUM(B13:M13) -> -4161653
A14: Contraction | B14: =-B10*$B$6 -> -96000 | C14: =-C10*$B$6 -> -97792 | D14: =-D10*$B$6 -> -99596.544 | E14: =-E10*$B$6 -> -101413.72 | F14: =-F10*$B$6 -> -103299.62 | G14: =-G10*$B$6 -> -105257.51 | H14: =-H10*$B$6 -> -107290.86 | I14: =-I10*$B$6 -> -109403.26 | ... M14: =-M10*$B$6 -> -118722.26 | N14: =SUM(B14:M14) -> -1280508.6
A15: Ending ARR | B15: =SUM(B10:B14) -> 24448000 | C15: =SUM(C10:C14) -> 24899136 | D15: =SUM(D10:D14) -> 25353430 | E15: =SUM(E10:E14) -> 25824904 | F15: =SUM(F10:F14) -> 26314378 | G15: =SUM(G10:G14) -> 26822714 | H15: =SUM(H10:H14) -> 27350815 | I15: =SUM(I10:I14) -> 27899629 | ... M15: =SUM(M10:M14) -> 30322700 | N15: =SUM(B15:M15) -> 3.2644986e+08
A16: Monthly Recognized Revenue | B16: =B15/12 -> 2037333.3 | C16: =C15/12 -> 2074928 | D16: =D15/12 -> 2112785.8 | E16: =E15/12 -> 2152075.3 | F16: =F15/12 -> 2192864.9 | G16: =G15/12 -> 2235226.2 | H16: =H15/12 -> 2279234.6 | I16: =I15/12 -> 2324969.1 | ... M16: =M15/12 -> 2526891.7 | N16: =SUM(B16:M16) -> 27204155
A18: FY26 Revenue | N18: =SUM(B16:M16) -> 27204155
B20: =1.09^(1/12)-1 -> 0.0072073233

Sheet Customer_Metrics
A1: Beginning ARR | B1: 24000000 | E1: NimbusDesk FY26 Customer Metrics Dashboard
A2: Total Customers | B2: 1200 | F2: =B16 -> 1.0873107 | J2: =B19 -> 19.071479 | N2: =B22 -> 4.8447205 | R2: =B15 -> 0.81403338
A3: Annual Gross Churn | B3: 0.14
A4: Gross Margin | B4: 0.78
A5: FY26 New ARR | B5: =SUM(Rev_Build!B11:M11) -> 4081809.9 | E5: KPI | G5: NRR | K5: CAC Payback | O5: LTV:CAC | S5: GRR
A6: New Customers | B6: 220 | E6: Status | G6: Healthy | K6: Needs Improvement | O6: Below Target | S6: Weak
A7: Total S&M Spend | B7: 9200000
A8: Monthly Expansion | B8: 0.024
A9: Monthly Churn | B9: 0.013 | M9: Key Matrics
A10: Monthly Contraction | B10: 0.004
A11: Acquisition S&M % | B11: 0.55
A15: Annual GRR | B15: =(1-B9-B10)^12 -> 0.81403338
A16: Annual NRR | B16: =(1+B8-B9-B10)^12 -> 1.0873107
A17: CAC | B17: =(B7*$B$11)/B6 -> 23000
A18: Avg New ARR per Customer | B18: =B5/B6 -> 18553.681
A19: CAC Payback (Months) | B19: =B17/(B18*$B$4)*12 -> 19.071479
A20: Avg ARR per Customer | B20: =B1/B2 -> 20000
A21: LTV | B21: =(B20*$B$4)/$B$3 -> 111428.57
A22: LTV:CAC | B22: =B21/B17 -> 4.8447205
A25: Metric | B25: Months
A26: Board Target | B26: 15
A27: Company Reported | B27: 19
A28: Model Result | B28: 34.7

Sheet Sales_Capacity
A1: Annual Quota per Rep | B1: 700000
A2: Quota Attainment | B2: 0.68
A3: Quota Carrying % | B3: 0.8
A4: New ARR Target | B4: 4081809.9
A5: December Sales HC | B5: 34.145833
A6: Starting Sales HC | B6: =30 -> 30
A7: Quota Carrying Reps | B7: =ROUND(B6*B3,0) -> 24
A8: Monthly Quota Per Rep | B8: =B1/12 -> 58333.333
A9: Monthly Capacity from Tenured Reps | B9: =B7*B8*B2 -> 952000
A12: Ramp Assumptions
A13: Months Since Hire | B13: 1 | C13: 2 | D13: 3 | E13: 4 | F13: 5+
A14: Productivity | B14: 0 | C14: 0 | D14: 0.5 | E14: 1 | F14: 1
A16: Capacity per Fully Ramped Cohort | B16: =2*$B$3*$B$8*$B$2 -> 63466.667
A17: Sales Hire Cohorts
A18: Cohort | B18: Jan | C18: Feb | D18: Mar | E18: Apr | F18: May | G18: Jun | H18: Jul | I18: Aug | J18: Sep | K18: Oct | L18: Nov | M18: Dec
A19: Feb Hires | B19: 0 | C19: 0 | D19: 0 | E19: 0.5 | F19: 1 | G19: 1 | H19: 1 | I19: 1 | J19: 1 | K19: 1 | L19: 1 | M19: 1
A20: May Hires | B20: 0 | C20: 0 | D20: 0 | E20: 0 | F20: 0 | G20: 0 | H20: 0.5 | I20: 1 | J20: 1 | K20: 1 | L20: 1 | M20: 1
A21: Aug Hires | B21: 0 | C21: 0 | D21: 0 | E21: 0 | F21: 0 | G21: 0 | H21: 0 | I21: 0 | J21: 0 | K21: 0.5 | L21: 1 | M21: 1
A22: Oct Hires | B22: 0 | C22: 0 | D22: 0 | E22: 0 | F22: 0 | G22: 0 | H22: 0 | I22: 0 | J22: 0 | K22: 0 | L22: 0 | M22: 0.5
A25: Monthly Capacity by Cohort
B26: Jan | C26: Feb | D26: Mar | E26: Apr | F26: May | G26: Jun | H26: Jul | I26: Aug | J26: Sep | K26: Oct | L26: Nov | M26: Dec
A27: Feb Hires Capacity | B27: =B19*$B$16 -> 0 | C27: =C19*$B$16 -> 0 | D27: =D19*$B$16 -> 0 | E27: =E19*$B$16 -> 31733.333 | F27: =F19*$B$16 -> 63466.667 | G27: =G19*$B$16 -> 63466.667 | H27: =H19*$B$16 -> 63466.667 | I27: =I19*$B$16 -> 63466.667 | ... M27: =M19*$B$16 -> 63466.667
A28: May Hires Capacity | B28: =B20*$B$16 -> 0 | C28: =C20*$B$16 -> 0 | D28: =D20*$B$16 -> 0 | E28: =E20*$B$16 -> 0 | F28: =F20*$B$16 -> 0 | G28: =G20*$B$16 -> 0 | H28: =H20*$B$16 -> 31733.333 | I28: =I20*$B$16 -> 63466.667 | ... M28: =M20*$B$16 -> 63466.667
A29: Aug Hires Capacity | B29: =B21*$B$16 -> 0 | C29: =C21*$B$16 -> 0 | D29: =D21*$B$16 -> 0 | E29: =E21*$B$16 -> 0 | F29: =F21*$B$16 -> 0 | G29: =G21*$B$16 -> 0 | H29: =H21*$B$16 -> 0 | I29: =I21*$B$16 -> 0 | ... M29: =M21*$B$16 -> 63466.667
A30: Oct Hires Capacity | B30: =B22*$B$16 -> 0 | C30: =C22*$B$16 -> 0 | D30: =D22*$B$16 -> 0 | E30: =E22*$B$16 -> 0 | F30: =F22*$B$16 -> 0 | G30: =G22*$B$16 -> 0 | H30: =H22*$B$16 -> 0 | I30: =I22*$B$16 -> 0 | ... M30: =M22*$B$16 -> 31733.333
A32: Total New Hire Capacity | B32: =SUM(B27:B30) -> 0 | C32: =SUM(C27:C30) -> 0 | D32: =SUM(D27:D30) -> 0 | E32: =SUM(E27:E30) -> 31733.333 | F32: =SUM(F27:F30) -> 63466.667 | G32: =SUM(G27:G30) -> 63466.667 | H32: =SUM(H27:H30) -> 95200 | I32: =SUM(I27:I30) -> 126933.33 | ... M32: =SUM(M27:M30) -> 222133.33
A33: Tenured Rep Capacity | B33: =$B$9 -> 952000 | C33: =$B$9 -> 952000 | D33: =$B$9 -> 952000 | E33: =$B$9 -> 952000 | F33: =$B$9 -> 952000 | G33: =$B$9 -> 952000 | H33: =$B$9 -> 952000 | I33: =$B$9 -> 952000 | ... M33: =$B$9 -> 952000
A34: Total Monthly Capacity | B34: =B32+B33 -> 952000 | C34: =C32+C33 -> 952000 | D34: =D32+D33 -> 952000 | E34: =E32+E33 -> 983733.33 | F34: =F32+F33 -> 1015466.7 | G34: =G32+G33 -> 1015466.7 | H34: =H32+H33 -> 1047200 | I34: =I32+I33 -> 1078933.3 | ... M34: =M32+M33 -> 1174133.3
A36: FY26 Ramp Adjusted Capacity | B36: =SUM(B34:M34) -> 12502933
A37: Coverage Ratio | B37: =B36/$B$4 -> 3.0630856
A39: The ramp-adjusted sales capacity is approximately $12.5M, providing 3.06x coverage against the FY26 New ARR target of $4.08M. Even after accounting for the productivity ramp of new hires, the sales organization has significantly more capacity than required to achieve the planned revenue target. Management should reassess either the New ARR target or the planned sales hiring plan, as maintaining excess sales capacity increases operating costs and conflicts with the board's objective of reducing cash burn.

Sheet Headcount_Plan
A1: Department | B1: Start HC | C1: Salary | D1: Loading | O1: Hiring Pace | P1: =CHOOSE(Scenarios!$F$2,Scenarios!$B$7,Scenarios!$C$7,Scenarios!$D$7) -> 1
A2: Sales | B2: 30 | C2: 380000 | D2: 0.35
A3: Marketing | B3: 18 | C3: 320000 | D3: 0.3
A4: R&D | B4: 45 | C4: 480000 | D4: 0.3
A5: Customer Success | B5: 22 | C5: 300000 | D5: 0.3
A6: G&A | B6: 25 | C6: 350000 | D6: 0.3
A12: Sales | B12: jan | C12: feb | D12: mar | E12: apr | F12: may | G12: jun | H12: jul | I12: aug | J12: sep | K12: oct | L12: nov | M12: dec
A13: Beginning HC | B13: =$B$2 -> 30 | C13: =B16 -> 29.7 | D13: =C16 -> 31.403 | E13: =D16 -> 31.08897 | F13: =E16 -> 30.77808 | G13: =F16 -> 32.470299 | H13: =G16 -> 32.145597 | I13: =H16 -> 31.824141 | J13: =I16 -> 33.505899 | ... M13: =L16 -> 34.49074
A14: New Hires | B14: =0 -> 0 | C14: =ROUNDDOWN(2*$P$1,0) -> 2 | D14: =0 -> 0 | E14: =0 -> 0 | F14: =ROUNDDOWN(2*$P$1,0) -> 2 | G14: =0 -> 0 | H14: =0 -> 0 | I14: =ROUNDDOWN(2*$P$1,0) -> 2 | J14: =0 -> 0 | K14: =ROUNDDOWN(2*$P$1,0) -> 2 | L14: =0 -> 0 | M14: =0 -> 0
A15: Attrition | B15: =-B13*1% -> -0.3 | C15: =-C13*1% -> -0.297 | D15: =-D13*1% -> -0.31403 | E15: =-E13*1% -> -0.3108897 | F15: =-F13*1% -> -0.3077808 | G15: =-G13*1% -> -0.32470299 | H15: =-H13*1% -> -0.32145597 | I15: =-I13*1% -> -0.31824141 | ... M15: =-M13*1% -> -0.3449074
A16: Ending HC | B16: =B13+B14+B15 -> 29.7 | C16: =C13+C14+C15 -> 31.403 | D16: =D13+D14+D15 -> 31.08897 | E16: =E13+E14+E15 -> 30.77808 | F16: =F13+F14+F15 -> 32.470299 | G16: =G13+G14+G15 -> 32.145597 | H16: =H13+H14+H15 -> 31.824141 | I16: =I13+I14+I15 -> 33.505899 | ... M16: =M13+M14+M15 -> 34.145833
A19: MARKETING
A20: Beginning HC | B20: =$B$3 -> 18 | C20: =B23 -> 17.82 | D20: =C23 -> 17.6418 | E20: =D23 -> 18.465382 | F20: =E23 -> 18.280728 | G20: =F23 -> 18.097921 | H20: =G23 -> 18.916942 | I20: =H23 -> 18.727772 | J20: =I23 -> 18.540495 | ... M20: =L23 -> 18.969923
A21: New Hires | B21: =0 -> 0 | C21: =0 -> 0 | D21: =ROUNDDOWN(1*$P$1,0) -> 1 | E21: =0 -> 0 | F21: =0 -> 0 | G21: =ROUNDDOWN(1*$P$1,0) -> 1 | H21: =0 -> 0 | I21: =0 -> 0 | J21: =ROUNDDOWN(1*$P$1,0) -> 1 | K21: 0 | L21: =0 -> 0 | M21: =0 -> 0
A22: Attrition | B22: =-B20*1% -> -0.18 | C22: =-C20*1% -> -0.1782 | D22: =-D20*1% -> -0.176418 | E22: =-E20*1% -> -0.18465382 | F22: =-F20*1% -> -0.18280728 | G22: =-G20*1% -> -0.18097921 | H22: =-H20*1% -> -0.18916942 | I22: =-I20*1% -> -0.18727772 | ... M22: =-M20*1% -> -0.18969923
A23: Ending HC | B23: =B20+B21+B22 -> 17.82 | C23: =C20+C21+C22 -> 17.6418 | D23: =D20+D21+D22 -> 18.465382 | E23: =E20+E21+E22 -> 18.280728 | F23: =F20+F21+F22 -> 18.097921 | G23: =G20+G21+G22 -> 18.916942 | H23: =H20+H21+H22 -> 18.727772 | I23: =I20+I21+I22 -> 18.540495 | ... M23: =M20+M21+M22 -> 18.780224
A26: R&D
A27: Beginning HC | B27: =$B$4 -> 45 | C27: =B30 -> 44.55 | D27: =C30 -> 45.1045 | E27: =D30 -> 45.653455 | F27: =E30 -> 46.19692 | G27: =F30 -> 46.734951 | H27: =G30 -> 47.267602 | I27: =H30 -> 47.794926 | J27: =I30 -> 48.316976 | ... M27: =L30 -> 49.852014
A28: New Hires | B28: =0 -> 0 | C28: =ROUNDDOWN(1*$P$1,0) -> 1 | D28: =ROUNDDOWN(1*$P$1,0) -> 1 | E28: =ROUNDDOWN(1*$P$1,0) -> 1 | F28: =ROUNDDOWN(1*$P$1,0) -> 1 | G28: =ROUNDDOWN(1*$P$1,0) -> 1 | H28: =ROUNDDOWN(1*$P$1,0) -> 1 | I28: =ROUNDDOWN(1*$P$1,0) -> 1 | J28: =ROUNDDOWN(1*$P$1,0) -> 1 | ... L28: =ROUNDDOWN(1*$P$1,0) -> 1 | M28: 0
A29: Attrition | B29: =-B27*1% -> -0.45 | C29: =-C27*1% -> -0.4455 | D29: =-D27*1% -> -0.451045 | E29: =-E27*1% -> -0.45653455 | F29: =-F27*1% -> -0.4619692 | G29: =-G27*1% -> -0.46734951 | H29: =-H27*1% -> -0.47267602 | I29: =-I27*1% -> -0.47794926 | ... M29: =-M27*1% -> -0.49852014
A30: Ending HC | B30: =B27+B28+B29 -> 44.55 | C30: =C27+C28+C29 -> 45.1045 | D30: =D27+D28+D29 -> 45.653455 | E30: =E27+E28+E29 -> 46.19692 | F30: =F27+F28+F29 -> 46.734951 | G30: =G27+G28+G29 -> 47.267602 | H30: =H27+H28+H29 -> 47.794926 | I30: =I27+I28+I29 -> 48.316976 | ... M30: =M27+M28+M29 -> 49.353494
A33: Customer Success
A34: Beginning HC | B34: =$B$5 -> 22 | C34: =B37 -> 21.78 | D34: =C37 -> 21.5622 | E34: =D37 -> 23.346578 | F34: =E37 -> 23.113112 | G34: =F37 -> 22.881981 | H34: =G37 -> 24.653161 | I34: =H37 -> 24.40663 | J34: =I37 -> 24.162563 | ... M34: =L37 -> 25.405111
A35: New Hires | B35: =0 -> 0 | C35: =0 -> 0 | D35: =ROUNDDOWN(2*$P$1,0) -> 2 | E35: =0 -> 0 | F35: =0 -> 0 | G35: =ROUNDDOWN(2*$P$1,0) -> 2 | H35: =0 -> 0 | I35: =0 -> 0 | J35: =ROUNDDOWN(2*$P$1,0) -> 2 | K35: =0 -> 0 | L35: =0 -> 0 | M35: =0 -> 0
A36: Attrition | B36: =-B34*1% -> -0.22 | C36: =-C34*1% -> -0.2178 | D36: =-D34*1% -> -0.215622 | E36: =-E34*1% -> -0.23346578 | F36: =-F34*1% -> -0.23113112 | G36: =-G34*1% -> -0.22881981 | H36: =-H34*1% -> -0.24653161 | I36: =-I34*1% -> -0.2440663 | ... M36: =-M34*1% -> -0.25405111
A37: Ending HC | B37: =B34+B35+B36 -> 21.78 | C37: =C34+C35+C36 -> 21.5622 | D37: =D34+D35+D36 -> 23.346578 | E37: =E34+E35+E36 -> 23.113112 | F37: =F34+F35+F36 -> 22.881981 | G37: =G34+G35+G36 -> 24.653161 | H37: =H34+H35+H36 -> 24.40663 | I37: =I34+I35+I36 -> 24.162563 | ... M37: =M34+M35+M36 -> 25.15106
A40: G&A
A41: Beginning HC | B41: =$B$6 -> 25 | C41: =B44 -> 24.75 | D41: =C44 -> 24.5025 | E41: =D44 -> 24.257475 | F41: =E44 -> 25.0149 | G41: =F44 -> 24.764751 | H41: =G44 -> 24.517104 | I41: =H44 -> 24.271933 | J41: =I44 -> 24.029213 | ... M41: =L44 -> 24.295622
A42: New Hires | B42: =0 -> 0 | C42: =0 -> 0 | D42: =0 -> 0 | E42: =ROUNDDOWN(1*$P$1,0) -> 1 | F42: =0 -> 0 | G42: =0 -> 0 | H42: =0 -> 0 | I42: =0 -> 0 | J42: =ROUNDDOWN(1*$P$1,0) -> 1 | K42: =0 -> 0 | L42: =0 -> 0 | M42: =0 -> 0
A43: Attrition | B43: =-B41*1% -> -0.25 | C43: =-C41*1% -> -0.2475 | D43: =-D41*1% -> -0.245025 | E43: =-E41*1% -> -0.24257475 | F43: =-F41*1% -> -0.250149 | G43: =-G41*1% -> -0.24764751 | H43: =-H41*1% -> -0.24517104 | I43: =-I41*1% -> -0.24271933 | ... M43: =-M41*1% -> -0.24295622
A44: Ending HC | B44: =B41+B42+B43 -> 24.75 | C44: =C41+C42+C43 -> 24.5025 | D44: =D41+D42+D43 -> 24.257475 | E44: =E41+E42+E43 -> 25.0149 | F44: =F41+F42+F43 -> 24.764751 | G44: =G41+G42+G43 -> 24.517104 | H44: =H41+H42+H43 -> 24.271933 | I44: =I41+I42+I43 -> 24.029213 | ... M44: =M41+M42+M43 -> 24.052665
A47: TOTAL COMPANY HC
A48: Ending HC | B48: =B16+B23+B30+B37+B44 -> 138.6 | C48: =C16+C23+C30+C37+C44 -> 140.214 | D48: =D16+D23+D30+D37+D44 -> 142.81186 | E48: =E16+E23+E30+E37+E44 -> 143.38374 | F48: =F16+F23+F30+F37+F44 -> 144.9499 | G48: =G16+G23+G30+G37+G44 -> 147.5004 | H48: =H16+H23+H30+H37+H44 -> 147.0254 | I48: =I16+I23+I30+I37+I44 -> 148.55515 | ... M48: =M16+M23+M30+M37+M44 -> 151.48328
A51: FULLY LOADED PEOPLE COST
A52: Sales Cost | B52: =B16*$C$2*(1+$D$2)/12 -> 1269675 | C52: =C16*$C$2*(1+$D$2)/12 -> 1342478.3 | D52: =D16*$C$2*(1+$D$2)/12 -> 1329053.5 | E52: =E16*$C$2*(1+$D$2)/12 -> 1315762.9 | F52: =F16*$C$2*(1+$D$2)/12 -> 1388105.3 | G52: =G16*$C$2*(1+$D$2)/12 -> 1374224.3 | H52: =H16*$C$2*(1+$D$2)/12 -> 1360482 | I52: =I16*$C$2*(1+$D$2)/12 -> 1432377.2 | ... M52: =M16*$C$2*(1+$D$2)/12 -> 1459734.4
A53: Marketing Cost | B53: =B23*$C$3*(1+$D$3)/12 -> 617760 | C53: =C23*$C$3*(1+$D$3)/12 -> 611582.4 | D53: =D23*$C$3*(1+$D$3)/12 -> 640133.24 | E53: =E23*$C$3*(1+$D$3)/12 -> 633731.91 | F53: =F23*$C$3*(1+$D$3)/12 -> 627394.59 | G53: =G23*$C$3*(1+$D$3)/12 -> 655787.31 | H53: =H23*$C$3*(1+$D$3)/12 -> 649229.44 | I53: =I23*$C$3*(1+$D$3)/12 -> 642737.14 | ... M53: =M23*$C$3*(1+$D$3)/12 -> 651047.77
A54: R&D Cost | B54: =B30*$C$4*(1+$D$4)/12 -> 2316600 | C54: =C30*$C$4*(1+$D$4)/12 -> 2345434 | D54: =D30*$C$4*(1+$D$4)/12 -> 2373979.7 | E54: =E30*$C$4*(1+$D$4)/12 -> 2402239.9 | F54: =F30*$C$4*(1+$D$4)/12 -> 2430217.5 | G54: =G30*$C$4*(1+$D$4)/12 -> 2457915.3 | H54: =H30*$C$4*(1+$D$4)/12 -> 2485336.1 | I54: =I30*$C$4*(1+$D$4)/12 -> 2512482.8 | ... M54: =M30*$C$4*(1+$D$4)/12 -> 2566381.7
A55: Customer Success Cost | B55: =B37*$C5*(1+$D5)/12 -> 707850 | C55: =C37*$C$5*(1+$D$5)/12 -> 700771.5 | D55: =D37*$C$5*(1+$D$5)/12 -> 758763.79 | E55: =E37*$C$5*(1+$D$5)/12 -> 751176.15 | F55: =F37*$C$5*(1+$D$5)/12 -> 743664.39 | G55: =G37*$C$5*(1+$D$5)/12 -> 801227.74 | H55: =H37*$C$5*(1+$D$5)/12 -> 793215.46 | I55: =I37*$C$5*(1+$D$5)/12 -> 785283.31 | J55: =J37*$C$5*(1+$D$5)/12 -> 842430.48 | ... M55: =M37*$C$5*(1+$D$5)/12 -> 817409.45
A56: G&A Cost | B56: =B44*$C$6*(1+$D$6)/12 -> 938437.5 | C56: =C44*$C$6*(1+$D$6)/12 -> 929053.12 | D56: =D44*$C$6*(1+$D$6)/12 -> 919762.59 | E56: =E44*$C$6*(1+$D$6)/12 -> 948481.63 | F56: =F44*$C$6*(1+$D$6)/12 -> 938996.82 | G56: =G44*$C$6*(1+$D$6)/12 -> 929606.85 | H56: =H44*$C$6*(1+$D$6)/12 -> 920310.78 | I56: =I44*$C$6*(1+$D$6)/12 -> 911107.67 | ... M56: =M44*$C$6*(1+$D$6)/12 -> 911996.9
A58: Total People Cost | B58: =SUM(B52:B56) -> 5850322.5 | C58: =SUM(C52:C56) -> 5929319.3 | D58: =SUM(D52:D56) -> 6021692.7 | E58: =SUM(E52:E56) -> 6051392.5 | F58: =SUM(F52:F56) -> 6128378.6 | G58: =SUM(G52:G56) -> 6218761.4 | H58: =SUM(H52:H56) -> 6208573.8 | I58: =SUM(I52:I56) -> 6283988.1 | ... M58: =SUM(M52:M56) -> 6406570.2
...

Sheet Dept_Budget
A1: Department | B1: People Cost (USD) | C1: Non-People Cost | D1: Total Budget | E1: Ending HC | F1: Cost per Head
A2: Sales | B2: =Headcount_Plan!B77 -> 4537819.7 | C2: =600000*70% -> 420000 | D2: =B2+C2 -> 4957819.7 | E2: =Headcount_Plan!M16 -> 34.145833 | F2: =D2/E2 -> 145195.45 | G2: =D2/OpEx_Budget!$N$28 -> 0.1669849
A3: Marketing | B3: =Headcount_Plan!B78 -> 2104161 | C3: =3200000+(1400000*25%) -> 3550000 | D3: =B3+C3 -> 5654161 | E3: =Headcount_Plan!M23 -> 18.780224 | F3: =D3/E3 -> 301069.94 | G3: =D3/OpEx_Budget!$N$28 -> 0.19043845
A4: R&D | B4: =Headcount_Plan!B79 -> 8062183.6 | C4: =1900000+(1400000*30%) -> 2320000 | D4: =B4+C4 -> 10382184 | E4: =Headcount_Plan!M30 -> 49.353494 | F4: =D4/E4 -> 210363.7 | G4: =D4/OpEx_Budget!$N$28 -> 0.34968352
A5: Customer Success | B5: =Headcount_Plan!B80 -> 2550807.8 | C5: =1400000*20% -> 280000 | D5: =B5+C5 -> 2830807.8 | E5: =Headcount_Plan!M37 -> 25.15106 | F5: =D5/E5 -> 112552.23 | G5: =D5/OpEx_Budget!$N$28 -> 0.095344763
A6: G&A | B6: =Headcount_Plan!B81 -> 3035256.2 | C6: =1100000+700000+500000+(1400000*25%)+(600000*30%) -> 2830000 | D6: =B6+C6 -> 5865256.2 | E6: =Headcount_Plan!M44 -> 24.052665 | F6: =D6/E6 -> 243850.57 | G6: =D6/OpEx_Budget!$N$28 -> 0.19754837
A9: A | B9: B
A10: Total Department Budget | B10: =SUM(D2:D6) -> 29690228
A11: Total OpEx (Phase 5) | B11: =OpEx_Budget!N28 -> 29690228
A12: Reconciliation Check | B12: =B10-B11 -> 0

Sheet OpEx_Budget
A1: Category | B1: Annual Cost | C1: Monthly Cost | D1: Maps To
A2: Marketing Programs | B2: 3200000 | C2: =B2/12 -> 266666.67 | D2: S&M
A3: Hosting / Cloud | B3: 1900000 | C3: =B3/12 -> 158333.33 | D3: Cost of Revenue
A4: Software & Tools | B4: 1400000 | C4: =B4/12 -> 116666.67 | D4: Shared
A5: Facilities & Office | B5: 1100000 | C5: =B5/12 -> 91666.667 | D5: G&A
A6: Professional Services | B6: 700000 | C6: =B6/12 -> 58333.333 | D6: G&A
A7: Travel & Entertainment | B7: 600000 | C7: =B7/12 -> 50000 | D7: Shared
A8: Other / Contingency | B8: 500000 | C8: =B8/12 -> 41666.667 | D8: G&A
A11: Category | B11: Jan | C11: Feb | D11: Mar | E11: Apr | F11: May | G11: Jun | H11: Jul | I11: Aug | J11: Sep | K11: Oct | L11: Nov | M11: Dec | N11: Annual Total
A12: Marketing Programs | B12: =$C2 -> 266666.67 | C12: =$C2 -> 266666.67 | D12: =$C2 -> 266666.67 | E12: =$C2 -> 266666.67 | F12: =$C2 -> 266666.67 | G12: =$C2 -> 266666.67 | H12: =$C2 -> 266666.67 | I12: =$C2 -> 266666.67 | ... M12: =$C2 -> 266666.67 | N12: =SUM(B12:M12) -> 3200000
A13: Hosting / Cloud | B13: =$C3 -> 158333.33 | C13: =$C3 -> 158333.33 | D13: =$C3 -> 158333.33 | E13: =$C3 -> 158333.33 | F13: =$C3 -> 158333.33 | G13: =$C3 -> 158333.33 | H13: =$C3 -> 158333.33 | I13: =$C3 -> 158333.33 | ... M13: =$C3 -> 158333.33 | N13: =SUM(B13:M13) -> 1900000
A14: Software & Tools | B14: =$C4 -> 116666.67 | C14: =$C4 -> 116666.67 | D14: =$C4 -> 116666.67 | E14: =$C4 -> 116666.67 | F14: =$C4 -> 116666.67 | G14: =$C4 -> 116666.67 | H14: =$C4 -> 116666.67 | I14: =$C4 -> 116666.67 | ... M14: =$C4 -> 116666.67 | N14: =SUM(B14:M14) -> 1400000
A15: Facilities & Office | B15: =$C5 -> 91666.667 | C15: =$C5 -> 91666.667 | D15: =$C5 -> 91666.667 | E15: =$C5 -> 91666.667 | F15: =$C5 -> 91666.667 | G15: =$C5 -> 91666.667 | H15: =$C5 -> 91666.667 | I15: =$C5 -> 91666.667 | ... M15: =$C5 -> 91666.667 | N15: =SUM(B15:M15) -> 1100000
A16: Professional Services | B16: =$C6 -> 58333.333 | C16: =$C6 -> 58333.333 | D16: =$C6 -> 58333.333 | E16: =$C6 -> 58333.333 | F16: =$C6 -> 58333.333 | G16: =$C6 -> 58333.333 | H16: =$C6 -> 58333.333 | I16: =$C6 -> 58333.333 | ... M16: =$C6 -> 58333.333 | N16: =SUM(B16:M16) -> 700000
A17: Travel & Entertainment | B17: =$C7 -> 50000 | C17: =$C7 -> 50000 | D17: =$C7 -> 50000 | E17: =$C7 -> 50000 | F17: =$C7 -> 50000 | G17: =$C7 -> 50000 | H17: =$C7 -> 50000 | I17: =$C7 -> 50000 | ... M17: =$C7 -> 50000 | N17: =SUM(B17:M17) -> 600000
A18: Other / Contingency | B18: =$C8 -> 41666.667 | C18: =$C8 -> 41666.667 | D18: =$C8 -> 41666.667 | E18: =$C8 -> 41666.667 | F18: =$C8 -> 41666.667 | G18: =$C8 -> 41666.667 | H18: =$C8 -> 41666.667 | I18: =$C8 -> 41666.667 | ... M18: =$C8 -> 41666.667 | N18: =SUM(B18:M18) -> 500000
A22: P&L Functional Summary
A23: Function | B23: jan | C23: feb | D23: mar | E23: apr | F23: may | G23: jun | H23: jul | I23: aug | J23: sep | K23: oct | L23: nov | M23: dec | N23: Annual Total
A24: Cost of Revenue | B24: =Headcount_Plan!B71+B13+(B14*20%) -> 374541.33 | C24: =Headcount_Plan!C71+C13+(C14*20%) -> 372612.58 | D24: =Headcount_Plan!D71+D13+(D14*20%) -> 388414.29 | E24: =Headcount_Plan!E71+E13+(E14*20%) -> 386346.82 | F24: =Headcount_Plan!F71+F13+(F14*20%) -> 384300.01 | G24: =Headcount_Plan!G71+G13+(G14*20%) -> 399984.85 | H24: =Headcount_Plan!H71+H13+(H14*20%) -> 397801.67 | I24: =Headcount_Plan!I71+I13+(I14*20%) -> 395640.32 | ... M24: =Headcount_Plan!M71+M13+(M14*20%) -> 404394.04 | N24: =SUM(B24:M24) -> 4730807.8
A25: Sales & Marketing | B25: =Headcount_Plan!B68+Headcount_Plan!B69+B12+(B14*25%)+(B17*70%) -> 845120.8 | C25: =Headcount_Plan!C68+Headcount_Plan!C69+C12+(C14*25%)+(C17*70%) -> 863274.93 | D25: =Headcount_Plan!D68+Headcount_Plan!D69+D12+(D14*25%)+(D17*70%) -> 867396.47 | E25: =Headcount_Plan!E68+Headcount_Plan!E69+E12+(E14*25%)+(E17*70%) -> 862030.84 | F25: =Headcount_Plan!F68+Headcount_Plan!F69+F12+(F14*25%)+(F17*70%) -> 880015.87 | G25: =Headcount_Plan!G68+Headcount_Plan!G69+G12+(G14*25%)+(G17*70%) -> 883970 | H25: =Headcount_Plan!H68+Headcount_Plan!H69+H12+(H14*25%)+(H17*70%) -> 878438.63 | I25: =Headcount_Plan!I68+Headcount_Plan!I69+I12+(I14*25%)+(I17*70%) -> 896259.58 | ... M25: =Headcount_Plan!M68+Headcount_Plan!M69+M12+(M14*25%)+(M17*70%) -> 905978.33 | N25: =SUM(B25:M25) -> 10611981
A26: Research & Development | B26: =Headcount_Plan!B70+(B14*30%) -> 666226.16 | C26: =Headcount_Plan!C70+(C14*30%) -> 674082.83 | D26: =Headcount_Plan!D70+(D14*30%) -> 681860.94 | E26: =Headcount_Plan!E70+(E14*30%) -> 689561.27 | F26: =Headcount_Plan!F70+(F14*30%) -> 697184.6 | G26: =Headcount_Plan!G70+(G14*30%) -> 704731.69 | H26: =Headcount_Plan!H70+(H14*30%) -> 712203.31 | I26: =Headcount_Plan!I70+(I14*30%) -> 719600.21 | ... M26: =Headcount_Plan!M70+(M14*30%) -> 734286.56 | N26: =SUM(B26:M26) -> 8482183.6
A27: General & Administrative | B27: =Headcount_Plan!B72+B15+B16+B18+(B14*25%)+(B17*30%) -> 491538.37 | C27: =Headcount_Plan!C72+C15+C16+C18+(C14*25%)+(C17*30%) -> 488981.32 | D27: =Headcount_Plan!D72+D15+D16+D18+(D14*25%)+(D17*30%) -> 486449.84 | E27: =Headcount_Plan!E72+E15+E16+E18+(E14*25%)+(E17*30%) -> 494275.2 | F27: =Headcount_Plan!F72+F15+F16+F18+(F14*25%)+(F17*30%) -> 491690.78 | G27: =Headcount_Plan!G72+G15+G16+G18+(G14*25%)+(G17*30%) -> 489132.2 | H27: =Headcount_Plan!H72+H15+H16+H18+(H14*25%)+(H17*30%) -> 486599.21 | I27: =Headcount_Plan!I72+I15+I16+I18+(I14*25%)+(I17*30%) -> 484091.56 | ... M27: =Headcount_Plan!M72+M15+M16+M18+(M14*25%)+(M17*30%) -> 484333.85 | N27: =SUM(B27:M27) -> 5865256.2
A28: Total OpEx | B28: =SUM(B24:B27) -> 2377426.7 | C28: =SUM(C24:C27) -> 2398951.7 | D28: =SUM(D24:D27) -> 2424121.5 | E28: =SUM(E24:E27) -> 2432214.1 | F28: =SUM(F24:F27) -> 2453191.3 | G28: =SUM(G24:G27) -> 2477818.7 | H28: =SUM(H24:H27) -> 2475042.8 | I28: =SUM(I24:I27) -> 2495591.7 | ... M28: =SUM(M24:M27) -> 2528992.8 | N28: =SUM(B28:M28) -> 29690228
A31: Analysis
A32: FY26 Revenue | B32: 27204155
A33: Cost of Revenue | B33: =N24 -> 4730807.8
A34: Gross Margin | B34: =(B32-B33)/B32 -> 0.82609981
A35: Total OpEx | B35: =N28 -> 29690228
A36: OpEx % of Revenue | B36: =B35/B32 -> 1.0913858

Sheet Cash_Flow
B1: Jan | C1: Feb | D1: Mar | E1: Apr | F1: May | G1: Jun | H1: Jul | I1: Aug | J1: Sep | K1: Oct | L1: Nov | M1: Dec
A2: Revenue | B2: =Rev_Build!B16 -> 2037333.3 | C2: =Rev_Build!C16 -> 2074928 | D2: =Rev_Build!D16 -> 2112785.8 | E2: =Rev_Build!E16 -> 2152075.3 | F2: =Rev_Build!F16 -> 2192864.9 | G2: =Rev_Build!G16 -> 2235226.2 | H2: =Rev_Build!H16 -> 2279234.6 | I2: =Rev_Build!I16 -> 2324969.1 | ... M2: =Rev_Build!M16 -> 2526891.7
A3: Total OpEx | B3: =OpEx_Budget!B28 -> 2377426.7 | C3: =OpEx_Budget!C28 -> 2398951.7 | D3: =OpEx_Budget!D28 -> 2424121.5 | E3: =OpEx_Budget!E28 -> 2432214.1 | F3: =OpEx_Budget!F28 -> 2453191.3 | G3: =OpEx_Budget!G28 -> 2477818.7 | H3: =OpEx_Budget!H28 -> 2475042.8 | I3: =OpEx_Budget!I28 -> 2495591.7 | ... M3: =OpEx_Budget!M28 -> 2528992.8
A4: Operating Burn | B4: =B2-B3 -> -340093.32 | C4: =C2-C3 -> -324023.66 | D4: =D2-D3 -> -311335.72 | E4: =E2-E3 -> -280138.79 | F4: =F2-F3 -> -260326.4 | G4: =G2-G3 -> -242592.58 | H4: =H2-H3 -> -195808.27 | I4: =I2-I3 -> -170622.57 | ... M4: =M2-M3 -> -2101.1095
A5: Non-Cash Add Back | B5: 150000 | C5: 150000 | D5: 150000 | E5: 150000 | F5: 150000 | G5: 150000 | H5: 150000 | I5: 150000 | J5: 150000 | K5: 150000 | L5: 150000 | M5: 150000
A6: Operating Cash Burn | B6: =B4+B5 -> -190093.32 | C6: =C4+C5 -> -174023.66 | D6: =D4+D5 -> -161335.72 | E6: =E4+E5 -> -130138.79 | F6: =F4+F5 -> -110326.4 | G6: =G4+G5 -> -92592.579 | H6: =H4+H5 -> -45808.267 | I6: =I4+I5 -> -20622.567 | ... M6: =M4+M5 -> 147898.89
A7: Beginning Cash | B7: 28000000 | C7: =B7+B6 -> 27809907 | D7: =C7+C6 -> 27635883 | E7: =D7+D6 -> 27474547 | F7: =E7+E6 -> 27344409 | G7: =F7+F6 -> 27234082 | H7: =G7+G6 -> 27141490 | I7: =H7+H6 -> 27095681 | J7: =I7+I6 -> 27075059 | ... M7: =L7+L6 -> 27166027
A8: Ending Cash | B8: =B7+B6 -> 27809907 | C8: =C7+C6 -> 27635883 | D8: =D7+D6 -> 27474547 | E8: =E7+E6 -> 27344409 | F8: =F7+F6 -> 27234082 | G8: =G7+G6 -> 27141490 | H8: =H7+H6 -> 27095681 | I8: =I7+I6 -> 27075059 | ... M8: =M7+M6 -> 27313926
A11: Analysis
A12: FY26 Operating Loss | B12: =SUM(B4:M4) -> -2486073.6
A13: FY26 Operating Cash Burn | B13: =SUM(B6:M6) -> -686073.61
A14: Average Monthly Cash Burn | B14: =AVERAGE(B6:M6) -> -57172.801
A15: Starting Cash | B15: =B7 -> 28000000
A16: Ending Cash | B16: =B8 -> 27809907
A17: Operating Cash Flow Breakeven | B17: October FY26
A20: Key Insights
A22: Monthly operating cash burn improves throughout FY26.
A23: Operating cash flow turns positive in October FY26.
A24: FY26 exits the year cash-generative.
A25: Deferred revenue has not yet been modeled; therefore, breakeven timing is conservative.
A26: Breakeven timing remains sensitive to New ARR and Expansion assumptions.

Sheet Three_Statement
A1: Income Statement (P&L) | B1: Opening | C1: Jan | D1: Feb | E1: Mar | F1: Apr | G1: May | H1: Jun | I1: Jul | J1: Aug | K1: Sep | L1: Oct | M1: Nov | N1: Dec | O1: FY26
A2: Revenue | C2: =Rev_Build!B16 -> 2037333.3 | D2: =Rev_Build!C16 -> 2074928 | E2: =Rev_Build!D16 -> 2112785.8 | F2: =Rev_Build!E16 -> 2152075.3 | G2: =Rev_Build!F16 -> 2192864.9 | H2: =Rev_Build!G16 -> 2235226.2 | I2: =Rev_Build!H16 -> 2279234.6 | J2: =Rev_Build!I16 -> 2324969.1 | ... N2: =Rev_Build!M16 -> 2526891.7 | O2: =SUM(C2:N2) -> 27204155
A3: Cost of Revenue | C3: =OpEx_Budget!B24 -> 374541.33 | D3: =OpEx_Budget!C24 -> 372612.58 | E3: =OpEx_Budget!D24 -> 388414.29 | F3: =OpEx_Budget!E24 -> 386346.82 | G3: =OpEx_Budget!F24 -> 384300.01 | H3: =OpEx_Budget!G24 -> 399984.85 | I3: =OpEx_Budget!H24 -> 397801.67 | J3: =OpEx_Budget!I24 -> 395640.32 | ... N3: =OpEx_Budget!M24 -> 404394.04 | O3: =SUM(C3:N3) -> 4730807.8
A4: Gross Profit | C4: =C2-C3 -> 1662792 | D4: =D2-D3 -> 1702315.4 | E4: =E2-E3 -> 1724371.5 | F4: =F2-F3 -> 1765728.5 | G4: =G2-G3 -> 1808564.8 | H4: =H2-H3 -> 1835241.3 | I4: =I2-I3 -> 1881432.9 | J4: =J2-J3 -> 1929328.8 | ... N4: =N2-N3 -> 2122497.6 | O4: =SUM(C4:N4) -> 22473347
A5: Gross Margin % | C5: =C4/C2 -> 0.816161 | D5: =D4/D2 -> 0.82042144 | E5: =E4/E2 -> 0.81616012 | F5: =F4/F2 -> 0.82047709 | G5: =G4/G2 -> 0.8247498 | H5: =H4/H2 -> 0.82105397 | I5: =I4/I2 -> 0.82546699 | J5: =J4/J2 -> 0.82982986 | ... N5: =N4/N2 -> 0.83996384 | O5: =SUM(C5:N5) -> 9.9077152
A6: Operating Expenses | C6: =SUM(OpEx_Budget!B25:B27) -> 2002885.3 | D6: =SUM(OpEx_Budget!C25:C27) -> 2026339.1 | E6: =SUM(OpEx_Budget!D25:D27) -> 2035707.3 | F6: =SUM(OpEx_Budget!E25:E27) -> 2045867.3 | G6: =SUM(OpEx_Budget!F25:F27) -> 2068891.2 | H6: =SUM(OpEx_Budget!G25:G27) -> 2077833.9 | I6: =SUM(OpEx_Budget!H25:H27) -> 2077241.2 | J6: =SUM(OpEx_Budget!I25:I27) -> 2099951.3 | ... N6: =SUM(OpEx_Budget!M25:M27) -> 2124598.7 | O6: =SUM(C6:N6) -> 24959421
A7: EBITDA | C7: =C4-C6 -> -340093.32 | D7: =D4-D6 -> -324023.66 | E7: =E4-E6 -> -311335.72 | F7: =F4-F6 -> -280138.79 | G7: =G4-G6 -> -260326.4 | H7: =H4-H6 -> -242592.58 | I7: =I4-I6 -> -195808.27 | J7: =J4-J6 -> -170622.57 | ... N7: =N4-N6 -> -2101.1095 | O7: =SUM(C7:N7) -> -2486073.6
A8: Depreciation & Amortization | C8: =150000 -> 150000 | D8: =150000 -> 150000 | E8: =150000 -> 150000 | F8: =150000 -> 150000 | G8: =150000 -> 150000 | H8: =150000 -> 150000 | I8: =150000 -> 150000 | J8: =150000 -> 150000 | ... N8: =150000 -> 150000 | O8: =SUM(C8:N8) -> 1800000
A9: EBIT | C9: =C7-C8 -> -490093.32 | D9: =D7-D8 -> -474023.66 | E9: =E7-E8 -> -461335.72 | F9: =F7-F8 -> -430138.79 | G9: =G7-G8 -> -410326.4 | H9: =H7-H8 -> -392592.58 | I9: =I7-I8 -> -345808.27 | J9: =J7-J8 -> -320622.57 | ... N9: =N7-N8 -> -152101.11 | O9: =SUM(C9:N9) -> -4286073.6
A10: Net Income | C10: =C9 -> -490093.32 | D10: =D9 -> -474023.66 | E10: =E9 -> -461335.72 | F10: =F9 -> -430138.79 | G10: =G9 -> -410326.4 | H10: =H9 -> -392592.58 | I10: =I9 -> -345808.27 | J10: =J9 -> -320622.57 | ... N10: =N9 -> -152101.11 | O10: =SUM(C10:N10) -> -4286073.6
A14: BALANCE SHEET
A16: ASSETS
A17: Cash | B17: 28000000 | C17: =C59 -> 28442987 | D17: =D59 -> 28148888 | E17: =E59 -> 27873887 | F17: =F59 -> 27614717 | G17: =G59 -> 27390007 | H17: =H59 -> 27188499 | I17: =I59 -> 27008245 | J17: =J59 -> 26878435 | ... N17: =N59 -> 26652360
A18: Accounts Receivable | B18: 2200000 | C18: =C2 -> 2037333.3 | D18: =D2 -> 2074928 | E18: =E2 -> 2112785.8 | F18: =F2 -> 2152075.3 | G18: =G2 -> 2192864.9 | H18: =H2 -> 2235226.2 | I18: =I2 -> 2279234.6 | J18: =J2 -> 2324969.1 | ... N18: =N2 -> 2526891.7
A19: Fixed Assets | B19: 3500000 | C19: =B19+120000-150000 -> 3470000 | D19: =C19+120000-150000 -> 3440000 | E19: =D19+120000-150000 -> 3410000 | F19: =E19+120000-150000 -> 3380000 | G19: =F19+120000-150000 -> 3350000 | H19: =G19+120000-150000 -> 3320000 | I19: =H19+120000-150000 -> 3290000 | J19: =I19+120000-150000 -> 3260000 | ... N19: =M19+120000-150000 -> 3140000
A20: -------------------
A21: Total Assets | B21: =SUM(B17:B19) -> 33700000 | C21: =SUM(C17:C19) -> 33950320 | D21: =SUM(D17:D19) -> 33663816 | E21: =SUM(E17:E19) -> 33396673 | F21: =SUM(F17:F19) -> 33146792 | G21: =SUM(G17:G19) -> 32932872 | H21: =SUM(H17:H19) -> 32743725 | I21: =SUM(I17:I19) -> 32577480 | ... N21: =SUM(N17:N19) -> 32319252
A23: LIABILITIES
A24: Accounts Payable | B24: 1800000 | C24: =C3+C6 -> 2377426.7 | D24: =D3+D6 -> 2398951.7 | E24: =E3+E6 -> 2424121.5 | F24: =F3+F6 -> 2432214.1 | G24: =G3+G6 -> 2453191.3 | H24: =H3+H6 -> 2477818.7 | I24: =I3+I6 -> 2475042.8 | J24: =J3+J6 -> 2495591.7 | ... N24: =N3+N6 -> 2528992.8
A25: Deferred Revenue | B25: 9600000 | C25: =B25 + (C2*8%) -> 9762986.7 | D25: =C25 + (D2*8%) -> 9928980.9 | E25: =D25 + (E2*8%) -> 10098004 | F25: =E25 + (F2*8%) -> 10270170 | G25: =F25 + (G2*8%) -> 10445599 | H25: =G25 + (H2*8%) -> 10624417 | I25: =H25 + (I2*8%) -> 10806756 | J25: =I25 + (J2*8%) -> 10992753 | ... N25: =M25 + (N2*8%) -> 11776332
A26: -------------------
A27: Total Liabilities | B27: =SUM(B24:B25) -> 11400000 | C27: =SUM(C24:C25) -> 12140413 | D27: =SUM(D24:D25) -> 12327933 | E27: =SUM(E24:E25) -> 12522125 | F27: =SUM(F24:F25) -> 12702384 | G27: =SUM(G24:G25) -> 12898790 | H27: =SUM(H24:H25) -> 13102236 | I27: =SUM(I24:I25) -> 13281799 | ... N27: =SUM(N24:N25) -> 14305325
A29: EQUITY
A30: Paid-in Capital | B30: =B21-B27-B31 -> 36300000 | C30: =B30 -> 36300000 | D30: =C30 -> 36300000 | E30: =D30 -> 36300000 | F30: =E30 -> 36300000 | G30: =F30 -> 36300000 | H30: =G30 -> 36300000 | I30: =H30 -> 36300000 | J30: =I30 -> 36300000 | ... N30: =M30 -> 36300000
A31: Retained Earnings | B31: -14000000 | C31: =B31+C10 -> -14490093 | D31: =C31+D10 -> -14964117 | E31: =D31+E10 -> -15425453 | F31: =E31+F10 -> -15855591 | G31: =F31+G10 -> -16265918 | H31: =G31+H10 -> -16658510 | I31: =H31+I10 -> -17004319 | J31: =I31+J10 -> -17324941 | ... N31: =M31+N10 -> -18286074
A32: -------------------
A33: Total Equity | B33: =SUM(B30:B31) -> 22300000 | C33: =C30+C31 -> 21809907 | D33: =D30+D31 -> 21335883 | E33: =E30+E31 -> 20874547 | F33: =F30+F31 -> 20444409 | G33: =G30+G31 -> 20034082 | H33: =H30+H31 -> 19641490 | I33: =I30+I31 -> 19295681 | J33: =J30+J31 -> 18975059 | ... N33: =N30+N31 -> 18013926
A35: Balance Check | B35: =B21-(B27+B33) -> 0 | C35: =C21-(C27+C33) -> 0 | D35: =D21-(D27+D33) -> 0 | E35: =E21-(E27+E33) -> 0 | F35: =F21-(F27+F33) -> 0 | G35: =G21-(G27+G33) -> 0 | H35: =H21-(H27+H33) -> 0 | I35: =I21-(I27+I33) -> 0 | ... N35: =N21-(N27+N33) -> 0
A42: CASH FLOW STATEMENT
A43: Operating Activities
A44: Net Income | C44: =C10 -> -490093.32 | D44: =D10 -> -474023.66 | E44: =E10 -> -461335.72 | F44: =F10 -> -430138.79 | G44: =G10 -> -410326.4 | H44: =H10 -> -392592.58 | I44: =I10 -> -345808.27 | J44: =J10 -> -320622.57 | ... N44: =N10 -> -152101.11
A45: Depreciation & Amortization | C45: =C8 -> 150000 | D45: =D8 -> 150000 | E45: =E8 -> 150000 | F45: =F8 -> 150000 | G45: =G8 -> 150000 | H45: =H8 -> 150000 | I45: =I8 -> 150000 | J45: =J8 -> 150000 | ... N45: =N8 -> 150000
A46: Change in Accounts Receivable | C46: =-(C18-B18) -> 162666.67 | D46: =-(D18-C18) -> -37594.667 | E46: =-(E18-D18) -> -37857.829 | F46: =-(F18-E18) -> -39289.501 | G46: =-(G18-F18) -> -40789.527 | H46: =-(H18-G18) -> -42361.304 | I46: =-(I18-H18) -> -44008.396 | J46: =-(J18-I18) -> -45734.545 | ... N46: =-(N18-M18) -> -53511.321
A47: Change in Accounts Payable | C47: =C24-B24 -> 577426.66 | D47: =D24-C24 -> 21525.007 | E47: =E24-D24 -> 25169.884 | F47: =F24-E24 -> 8092.572 | G47: =G24-F24 -> 20977.132 | H47: =H24-G24 -> 24627.488 | I47: =I24-H24 -> -2775.9167 | J47: =J24-I24 -> 20548.845 | ... N47: =N24-M24 -> -17632.924
A48: Change in Deferred Revenue | C48: =C25-B25 -> 162986.67 | D48: =D25-C25 -> 165994.24 | E48: =E25-D25 -> 169022.87 | F48: =F25-E25 -> 172166.03 | G48: =G25-F25 -> 175429.19 | H48: =H25-G25 -> 178818.09 | I48: =I25-H25 -> 182338.76 | J48: =J25-I25 -> 185997.53 | ... N48: =N25-M25 -> 202151.33
A49: Cash Flow from Operations | C49: =C44+C45+C46+C47+C48 -> 562986.67 | D49: =D44+D45+D46+D47+D48 -> -174099.08 | E49: =E44+E45+E46+E47+E48 -> -155000.8 | F49: =F44+F45+F46+F47+F48 -> -139169.69 | G49: =G44+G45+G46+G47+G48 -> -104709.6 | H49: =H44+H45+H46+H47+H48 -> -81508.302 | I49: =I44+I45+I46+I47+I48 -> -60253.814 | J49: =J44+J45+J46+J47+J48 -> -9810.7385 | ... N49: =N44+N45+N46+N47+N48 -> 128905.98
A50: Investing Activities
A51: Capital Expenditure (CapEx) | C51: =-120000 -> -120000 | D51: =-120000 -> -120000 | E51: =-120000 -> -120000 | F51: =-120000 -> -120000 | G51: =-120000 -> -120000 | H51: =-120000 -> -120000 | I51: =-120000 -> -120000 | J51: =-120000 -> -120000 | ... N51: =-120000 -> -120000
A52: Cash Flow from Investing | C52: =C51 -> -120000 | D52: =D51 -> -120000 | E52: =E51 -> -120000 | F52: =F51 -> -120000 | G52: =G51 -> -120000 | H52: =H51 -> -120000 | I52: =I51 -> -120000 | J52: =J51 -> -120000 | ... N52: =N51 -> -120000
A53: Financing Activities
...

Sheet Scenarios
A1: Scenario Driver | B1: Base | C1: Upside | D1: Downside | F1: Scenario | I1: Metric | J1: Base | K1: Upside | L1: Downside
A2: New ARR (Q1 Monthly) | B2: 280000 | C2: 340000 | D2: 220000 | F2: 1 | I2: FY26 Revenue | J2: =Three_Statement!O2 -> 27204155 | K2: 29568820 | L2: 24119909
A3: New ARR MoM Growth | B3: 0.05 | C3: 0.07 | D3: 0.03 | I3: EBITDA | J3: =Three_Statement!O7 -> -2486073.6 | K3: -121408.44 | L3: -5570319.8
A4: Expansion | B4: 0.024 | C4: 0.03 | D4: 0.015 | I4: Net Income | J4: =Three_Statement!O10 -> -4286073.6 | K4: -1921408.4 | L4: -7370319.8
A5: Churn | B5: 0.013 | C5: 0.01 | D5: 0.018 | I5: December Ending Cash | J5: =Three_Statement!N59 -> 26652360 | K5: 28798181 | L5: 23818237
A6: Contraction | B6: 0.004 | C6: 0.003 | D6: 0.006
A7: Hiring Pace | B7: 1 | C7: 1.2 | D7: 0.5 | I7: NRR | J7: =(1+B4-B5-B6)^12 -> 1.0873107 | K7: =(1+C4-C5-C6)^12 -> 1.2241974 | L7: =(1+D4-D5-D6)^12 -> 0.89718882

Sheet Variance_Analysis
A1: Line Item | B1: Budget | C1: Actual | D1: Variance ($) | E1: Variance (%) | F1: F/U | G1: Material?
A2: Revenue | B2: =SUM(Rev_Build!B16:D16) -> 6225047.2 | C2: 6050000 | D2: =C2-B2 -> -175047.16 | E2: =D2/B2 -> -0.028119813 | F2: =IF(D2>=0,"F","U") -> U | G2: =IF(AND(ABS(D2)>50000,ABS(E2)>5%),"Material","")
A3: New ARR Added | B3: =SUM(Rev_Build!B11:D11) -> 840000 | C3: 760000 | D3: =C3-B3 -> -80000 | E3: =D3/B3 -> -0.095238095 | F3: =IF(D3>=0,"F","U") -> U | G3: =IF(AND(ABS(D3)>50000,ABS(E3)>5%),"Material","") -> Material
A4: Cost of Revenue | B4: =SUM(Three_Statement!C3:E3) -> 1135568.2 | C4: 1480000 | D4: =C4-B4 -> 344431.8 | E4: =D4/B4 -> 0.3033123 | F4: =IF(D4<=0,"F","U") -> U | G4: =IF(AND(ABS(D4)>50000,ABS(E4)>5%),"Material","") -> Material
A5: Sales & Marketing | B5: =SUM(OpEx_Budget!B25:D25) -> 2575792.2 | C5: 3150000 | D5: =C5-B5 -> 574207.8 | E5: =D5/B5 -> 0.22292474 | F5: =IF(D5<=0,"F","U") -> U | G5: =IF(AND(ABS(D5)>50000,ABS(E5)>5%),"Material","") -> Material
A6: R&D | B6: =SUM(OpEx_Budget!B26:D26) -> 2022169.9 | C6: 2240000 | D6: =C6-B6 -> 217830.07 | E6: =D6/B6 -> 0.10772095 | F6: =IF(D6<=0,"F","U") -> U | G6: =IF(AND(ABS(D6)>50000,ABS(E6)>5%),"Material","") -> Material
A7: G&A | B7: =SUM(OpEx_Budget!B27:D27) -> 1466969.5 | C7: 1320000 | D7: =C7-B7 -> -146969.54 | E7: =D7/B7 -> -0.10018582 | F7: =IF(D7<=0,"F","U") -> F | G7: =IF(AND(ABS(D7)>50000,ABS(E7)>5%),"Material","") -> Material
A8: Ending Headcount | B8: =Headcount_Plan!D48 -> 142.81186 | C8: 142 | D8: =C8-B8 -> -0.81186 | E8: =D8/B8 -> -0.005684822 | F8: =IF(D8>=0,"F","U") -> U | G8: =IF(AND(ABS(D8)>50000,ABS(E8)>5%),"Material","")
